# 要約 
このディスカッションは、Kaggleの「LLM 20 Questions」コンペティションにおけるエラーに関するものです。ユーザーのDominique Nocitoは、多くのゲームでエラーが発生し、エピソードが見つからない状況が増えていると報告しています。具体的には、エピソードID 55104943の再生が読み込めず、エラーメッセージには「string index out of range」と表示されているとのことです。

このエラーは、Nocitoの検証実行にも影響を与えている可能性があり、エラーの原因は、コード内の文字列インデックスが範囲外であることにあると推測されています。

コンペティションの主催者であるBovard Doerschuk-Tiberiは、この問題を認識しており、すでに解決済みであるとコメントしています。また、Nocitoの報告に感謝し、迅速な修正を約束しています。


---
# エピソードが見つからない/全体的なエラー

**Dominique Nocito** *2024年6月18日 火曜日 22:49:17 日本標準時* (0票)

多くのゲームで、全員がエラーを起こし、エピソードが見つからない状況が増えています。エピソードの再生を読み込めません: 55104943。

この原因となった可能性のあるものは、私の検証実行の1つにも影響を与えていると思います。この場合の再生には、次のエラーがあります。{'error': 'string index out of range', 'trace': 'Traceback (most recent call last):\n  File "/opt/conda/lib/python3.10/site-packages/kaggle_environments/main.py", line 254, in action_handler\n    return action_run(args)\n  File "/opt/conda/lib/python3.10/site-packages/kaggle_environments/main.py", line 170, in action_run\n    env.run(args.agents)\n  File "/opt/conda/lib/python3.10/site-packages/kaggle_environments/core.py", line 268, in run\n    self.step(actions, logs)\n  File "/opt/conda/lib/python3.10/site-packages/kaggle_environments/core.py", line 232, in step\n    self.state = self.__run_interpreter(action_state, logs)\n  File "/opt/conda/lib/python3.10/site-packages/kaggle_environments/core.py", line 605, in __run_interpreter\n    raise e\n  File "/opt/conda/lib/python3.10/site-packages/kaggle_environments/core.py", line 583, in __run_interpreter\n    new_state = structify(self.interpreter(\n  File "/opt/conda/lib/python3.10/site-packages/kaggle_environments/envs/llm_20_questions/llm_20_questions.py", line 206, in interpreter\n    [one_guessed, one_bad_guess] = guesser_action(active1, inactive1, step)\n  File "/opt/conda/lib/python3.10/site-packages/kaggle_environments/envs/llm_20_questions/llm_20_questions.py", line 123, in guesser_action\n    if active.action and keyword_guessed(active.action):\n  File "/opt/conda/lib/python3.10/site-packages/kaggle_environments/envs/llm_20_questions/llm_20_questions.py", line 298, in keyword_guessed\n    if compare_words(guess, keyword):\n  File "/opt/conda/lib/python3.10/site-packages/kaggle_environments/envs/llm_20_questions/llm_20_questions.py", line 287, in compare_words\n    if a[-1] == "s" and a[:-1] == b:\nIndexError: string index out of range\n'}

---
# 他のユーザーからのコメント
> ## Bovard Doerschuk-Tiberi
> 
> 今は解決済みのはずです。
> 
> 
> 
---
> ## Bovard Doerschuk-Tiberi
> 
> ご報告ありがとうございます！ すぐに修正します。
> 
> 
> 
---

