# 要約 
ディスカッションでは、参加者がコンペティションでのスコアリングに関する質問をしており、特に「Err」やスコアのラベル（1st、3rdなど）の意味について議論しています。投稿者のCchristoCは、エージェントのスコアが異なる理由や、エラーが発生する原因について疑問を持っています。フォロワーからは、エラーがゲーム中に例外を投げたことを示すことや、メモリ不足が絡む可能性があるというアドバイスが寄せられています。また、CchristoCは「3rd」が負けたグループを指すことが分かったと報告しています。全体として、エージェントのパフォーマンスの向上やエラー解決に向けた情報共有が行われています。

---
# スコアリングに関する質問
**CchristoC** *2024年7月6日（土）01:32:10（日本標準時）* (0票)
スコア結果の名前の横にある[]内の1st、3rdなどはどのように機能するのでしょうか？ 
私のエージェントの一つでは、Errが-184と-95を示しています。 
この3rdの部分は-118を示すことがあり、別の[Err]も-118を示します。 
一方、この試合では単に-5になることもあります。 
これらは何を意味するのでしょうか？ 
Errを示しているエージェントのログは以下の通りです：
[[{"duration": 44.487901, "stdout": "", "stderr": "\rLoading checkpoint shards:   0%|          | 0/4 [00:00<?, ?it/s]\rLoading checkpoint shards:  25%|##5       | 1/4 [00:01<00:05,  1.72s/it]\rLoading checkpoint shards:  50%|#####     | 2/4 [00:03<00:03,  1.69s/it]\rLoading checkpoint shards:  75%|#######5  | 3/4 [00:09<00:03,  3.58s/it]\rLoading checkpoint shards: 100%|##########| 4/4 [00:09<00:00,  2.33s/it]\n"}],
 [{"duration": 13.157402, "stdout": "", "stderr": ""}],
 // (以下省略)
  [{"duration": 15.000276, "stdout": "", "stderr": ""}],
 [{"duration": 9.141473, "stdout": "", "stderr": "Traceback (most recent call last):\n  File \"/opt/conda/lib/python3.10/site-packages/kaggle_environments/agent.py\", line 159, in act\n    action = self.agent(*args)\n  File \"/opt/conda/lib/python3.10/site-packages/kaggle_environments/agent.py\", line 130, in callable_agent\n    agent(*args) \\\n  File \"/kaggle_simulations/agent/main.py\", line 193, in agent\n    response = robot.on(mode = \"asking\", obs = obs)\n  File \"/kaggle_simulations/agent/main.py\", line 47, in on\n    output = self.asker(obs)\n  File \"/kaggle_simulations/agent/main.py\", line 141, in asker\n    output = generate_answer(chat_template)\n  File \"/kaggle_simulations/agent/main.py\", line 28, in generate_answer\n    out_ids = model.generate(**inp_ids,max_new_tokens=15).squeeze()\n  File \"/opt/conda/lib/python3.10/site-packages/torch/utils/_contextlib.py\", line 115, in decorate_context\n    return func(*args, **kwargs)\n  File \"/opt/conda/lib/python3.10/site-packages/transformers/generation/utils.py\", line 1758, in generate\n    result = self._sample(\n  File \"/opt/"}]]

---
# 他のユーザーからのコメント
> ## Araik Tamazian
> 
> "Err"は、ゲーム中にコードが例外を投げたことを意味します。
> 
> ---
> ## Krens
> 
> 私も同じErrに遭遇しましたが、解決しましたか？
> 
> > ## CchristoCTopic Author
> > 
> > エージェントのログを確認してください。タイムアウトでなく、試合の途中でErrが発生した場合（それまでに成功したターンがある場合）、おそらくメモリ不足の問題です。 （もしあなたのチームメイトのエージェントが長いプロンプトを使用しているなら、それが原因かもしれません。自分のプロンプトを短くするか、彼らのプロンプトが長すぎる場合は切り詰めるか、あるいは小さいモデルを使用するなどの他の解決策を考えてください。）
> > 
> > 
> > > ## Krens
> > > > ありがとうございます、たぶんメモリ不足の問題ですね。私のErrエージェントは常に回答者で、プロンプトに履歴情報を追加したため、プロンプトが長すぎました。
> > > > 
> > > > 
> ---
> ## CchristoCTopic Author
> 
> 結局、3rdは負けたグループを意味していることがわかりました。
> 
> ---
