# 要約 
このディスカッションは、Kaggleの「LLM 20 Questions」コンペティションにおける提出に関する問題についてです。

**Naive Experimentalist**というユーザーは、Flan T5 largeモデルをベースにしたエージェントを提出しようとした際に、検証ラウンドでエラーが発生し、ログが空であるという問題に遭遇しました。

ユーザーは、ノートブックの実行ログにもエラーがなく、以前はログにエラーが表示されていたため、問題の解決策が分からず、どのようにデバッグすれば良いのか質問しています。

**waechter**というユーザーは、エージェント関数にprintを追加することで、stdoutに表示されるためデバッグできることを提案しました。

**Naive Experimentalist**は、検証ラウンドの問題はプレイ中にノートブックからエラーが発生した場合にのみ発生すると考えていたため、従来のprintベースのデバッグは行っていなかったことを認め、waechterの提案を試してみることを表明しました。

**玛丽·伊丽莎白·马特米斯**というユーザーは、同じ問題に遭遇しており、解決策が分からないとコメントしています。

**Naive Experimentalist**は、その後、問題の原因を突き止めました。Kaggle環境は、エージェントを実行しようとして適切な名前と一致しない場合、ファイル内で最後に定義された関数を呼び出すことが分かりました。

ユーザーは、Kaggle環境が直接エージェントを呼び出すように、エージェントを正しく命名する方法がまだ分からないと述べています。今のところ、obs.roleに応じて適切なエージェントを呼び出すdef proxy(obs)関数を最後に定義することで、この問題を回避しています。


---
# 提出に関する問題

**Naive Experimentalist** *2024年6月14日 04:45:36 GMT+0900 (日本標準時)* (2票)

こんにちは。

私はflan t5 largeモデルをベースにした、非常に初歩的なエージェントを提出することができました。
そして、GemmaとFlan T5の両方を使った、より賢いエージェントを開発しました。提出しようとすると、検証ラウンドでエラーが発生しますが、ログは空です。この問題の解決策が全く分かりません。どのようにデバッグすれば良いのでしょうか？以前、検証ラウンドで問題が発生したときは、ログにエラーが表示されていました。

私のログは以下のようになっています。

log0: [[{"duration": 26.110363, "stdout": "", "stderr": ""}]]
log1: [[{"duration": 26.111393, "stdout": "", "stderr": ""}]]

ノートブックの実行ログにもエラーはありません: 483.4秒で正常に実行されました。

全くお手上げ状態です。以前、このような状況に遭遇した方がいれば教えてください。

**更新 (2024年6月14日):**

徹底的な分析の結果、Kaggle環境は、エージェントを実行しようとして適切な名前と一致しない場合、ファイル内で最後に定義された関数を呼び出すことが分かりました。これは他の皆さんにとっては当たり前のことかもしれませんが、私にとっては驚きでした。

ちなみに、Kaggle環境が直接エージェントを呼び出すように、エージェントを正しく命名する方法はまだ分かりません。今のところ、obs.roleに応じて適切なエージェントを呼び出すdef proxy(obs)関数を最後に定義することで、この問題を回避しています。

---
# 他のユーザーからのコメント

> ## waechter
> 
> デバッグのためにエージェント関数にprintを追加できます。stdoutに表示されます。
> 
> 
> 
> > ## Naive ExperimentalistTopic Author
> > 
> > 仰る通りです。私は検証ラウンドの問題は、プレイ中にノートブックからエラーが発生した場合にのみ発生すると考えていたので、従来のprintベースのデバッグは行いませんでした。やってみます。ありがとうございます。
> > 
> > 
> > 
---
> ## 玛丽·伊丽莎白·马特米斯
> 
> 私も全く分かりません。
> 
> 
> 
---

