# 要約 
ディスカッションは、コンペティション参加者がノートブックを提出する際に直面する「バリデーションエピソードが失敗しました（エラー）」についての問題を共有しています。参加者の一人である**tiny wood**さんは初心者で、ログが空で原因がわからないと述べています。

他のユーザーは同様の問題に直面しており、**davide**さんはエージェントのログがエラーを示していることを報告。その内容は、無効な構文を示すもので、エージェントのコードに何か問題がある可能性を指摘しています。他にも、**OminousDude**さんがログの二種類（エージェント0とエージェント1）を確認するよう提案し、**Code Hacker**さんも助けを求めています。 

さらに、**Krens**さんは、エージェントが「はい」または「いいえ」以外の回答を返したことやタイムアウトの注意、文字数制限の確認が重要であるとアドバイスしています。このディスカッションは、ノートブックの提出時に遭遇する問題に対するサポートと情報共有の場となっています。

---


<style>
.column-left{
  float: left;
  width: 47.5%;
  text-align: left;
}
.column-right{
  float: right;
  width: 47.5%;
  text-align: left;
}
.column-one{
  float: left;
  width: 100%;
  text-align: left;
}
</style>


<div class="column-left">

# original

# Submit problem(please help me)

**tiny wood** *Fri Jul 05 2024 09:43:09 GMT+0900 (日本標準時)* (1 votes)

I am a beginner in this competition.

I just tried to submit a notebook but it's keep saying "Validation Episode failed(Error)".

I also try to read the log after failure, but the log is empty

What is the problem?



---

 # Comments from other users

> ## davide
> 
> I am having the same issue, and it does not seem related to my code or to the agent's behavior.
> 
> This is the log I see from one of the agent:
> 
> [[{"duration": 0.002077, "stdout": "", "stderr": "Traceback (most recent call last):\n  File \"/opt/conda/lib/python3.10/site-packages/kaggle_environments/agent.py\", line 43, in get_last_callable\n    code_object = compile(raw, path, \"exec\")\n  File \"/kaggle_simulations/agent/main.py\", line 1\n    include the main.py code under this for submission\n            ^^^\nSyntaxError: invalid syntax\n\nDuring handling of the above exception, another exception occurred:\n\nTraceback (most recent call last):\n  File \"/opt/conda/lib/python3.10/site-packages/kaggle_environments/agent.py\", line 159, in act\n    action = self.agent(*args)\n  File \"/opt/conda/lib/python3.10/site-packages/kaggle_environments/agent.py\", line 125, in callable_agent\n    agent = get_last_callable(raw_agent, path=raw) or raw_agent\n  File \"/opt/conda/lib/python3.10/site-packages/kaggle_environments/agent.py\", line 64, in get_last_callable\n    raise InvalidArgument(\"Invalid raw Python: \" + repr(e))\nkaggle_environments.errors.InvalidArgument: Invalid raw Python: SyntaxError('invalid syntax', ('/kaggle_simulatio"}]]
> 
> Maybe anyone can help? [@bovard](https://www.kaggle.com/bovard) 
> 
> 
> 


---

> ## OminousDude
> 
> There are two logs: Agent 0 and Agent 1. Are you sure that you check both of them?
> 
> 
> 


---

> ## Code Hacker
> 
> Me too… Help me…
> 
> 
> 
> > ## Krens
> > 
> > The last time I encountered "Validation Episode failed (Error)" was because I removed the restrictions on the answers "yes" and "no" during debugging, which resulted in the error being thrown when the agent answered other answers during submission. In addition, you also need to pay attention to whether the run timeout, whether the number of characters exceeds the limit, etc.
> > 
> > 
> > 


---



</div>
<div class="column-right">

# 日本語訳

# 提出に関する問題（助けてください）
**tiny wood** *2024年7月5日 金曜日 09:43:09 GMT+0900（日本標準時）* (1票)
私はこのコンペティションの初心者です。
ノートブックを提出しようとしたのですが、「バリデーションエピソードが失敗しました（エラー）」と表示され続けます。
失敗後のログも読み取ろうとしましたが、ログは空でした。
問題は何でしょうか？
---
 # 他のユーザーからのコメント
> ## davide
> 
> 私も同じ問題に直面しており、自分のコードやエージェントの動作には関係ないようです。
> 
> こちらがエージェントの一つからのログです：
> 
> [[{"duration": 0.002077, "stdout": "", "stderr": "Traceback (most recent call last):\n  File \"/opt/conda/lib/python3.10/site-packages/kaggle_environments/agent.py\", line 43, in get_last_callable\n    code_object = compile(raw, path, \"exec\")\n  File \"/kaggle_simulations/agent/main.py\", line 1\n    include the main.py code under this for submission\n            ^^^\nSyntaxError: invalid syntax\n\nDuring handling of the above exception, another exception occurred:\n\nTraceback (most recent call last):\n  File \"/opt/conda/lib/python3.10/site-packages/kaggle_environments/agent.py\", line 159, in act\n    action = self.agent(*args)\n  File \"/opt/conda/lib/python3.10/site-packages/kaggle_environments/agent.py\", line 125, in callable_agent\n    agent = get_last_callable(raw_agent, path=raw) or raw_agent\n  File \"/opt/conda/lib/python3.10/site-packages/kaggle_environments/agent.py\", line 64, in get_last_callable\n    raise InvalidArgument(\"Invalid raw Python: \" + repr(e))\nkaggle_environments.errors.InvalidArgument: Invalid raw Python: SyntaxError('invalid syntax', ('/kaggle_simulatio"}]]
> 
> 誰か助けてくれませんか？ [@bovard](https://www.kaggle.com/bovard) 
> 
> ---
> ## OminousDude
> 
> エージェントには二つのログがあります：エージェント0とエージェント1。両方を確認しましたか？
> 
> ---
> ## Code Hacker
> 
> 私も同じです…助けてください…
> 
> > ## Krens
> > 
> > 最後に「バリデーションエピソードが失敗しました（エラー）」が発生したのは、デバッグ中に「はい」と「いいえ」の回答制限を取り除いたためで、提出時に他の回答をエージェントがしたときにエラーが発生しました。それに加えて、タイムアウトに注意することや、文字数が制限を超えていないかも確認する必要があります。
> > 
> > 


</div>